Workbook

Sheet Baseline & Tariff Impact
B2: TOYOTA U.S. TARIFF RESPONSE
B3: Comprehensive Revenue & Cost Drivers (JPY Millions)
B5: Toyota U.S. Strategic Revenue & Cost Model (JPY Millions)
C7: Historical | F7: Projected
C8: 2023 | D8: 2024 | E8: 2025 | F8: 2026 | G8: 2027 | H8: 2028 | I8: 2029 | J8: 2030 | K8: 2035 | L8: 2040
B10: Baseline Scenario (With 200% Tariff Impact)
B12: Total Global Revenue (U.S. Market) | C12: 37154258 | D12: 45095325 | E12: 48036704 | F12: 44183226 | G12: 46226334 | H12: 47661378 | I12: 49108467 | J12: 50581897 | K12: 62443844 | L12: 75473558
B13: Annual Growth Rate (%) | C13: 0.184 | D13: 0.2137 | E13: 0.0652 | F13: =(F12-E12)/E12 -> -0.080219451 | G13: =(G12-F12)/F12 -> 0.046241712 | H13: =(H12-G12)/G12 -> 0.031043863 | I13: =(I12-H12)/H12 -> 0.030361879 | J13: =(J12-I12)/I12 -> 0.030003584 | K13: =(K12-J12)/J12 -> 0.23450973 | L13: =(L12-K12)/K12 -> 0.20866291
B15: Impact Note: Tariff causes PERMANENT revenue loss - 2026 onward shows 42% sustained reduction vs. no-tariff baseline
B16: Revenue Loss vs. No-Tariff Scenario | F16: 6024986 | G16: 6303592 | H16: 6499279 | I16: 6696610 | J16: 6897332 | K16: 8515070 | L16: 10428213
B20: Strategic Response: 2-Phase Production Relocation
B22: Phase 1: RAV4 Prime (2026+) | F22: ='Strategic Revenue Model'!C70 -> 351999.42 | G22: ='Strategic Revenue Model'!D70 -> 492799.18 | H22: ='Strategic Revenue Model'!E70 -> 492799.18 | I22: ='Strategic Revenue Model'!F70 -> 492799.18 | J22: ='Strategic Revenue Model'!G70 -> 492799.18 | K22: ='Strategic Revenue Model'!H70 -> 492799.18 | L22: ='Strategic Revenue Model'!I70 -> 492799.18
B23: Phase 2: Standalone Plant (2030+) | J23: ='Strategic Revenue Model'!G198 -> 798458.29 | K23: ='Strategic Revenue Model'!H198 -> 1596916.6 | L23: ='Strategic Revenue Model'!I198 -> 1596916.6
B25: Total Revenue Recovery | F25: =SUM(F22:F23) -> 351999.42 | G25: =SUM(G22:G23) -> 492799.18 | H25: =SUM(H22:H23) -> 492799.18 | I25: =SUM(I22:I23) -> 492799.18 | J25: =SUM(J22:J23) -> 1291257.5 | K25: =SUM(K22:K23) -> 2089715.8 | L25: =SUM(L22:L23) -> 2089715.8 | N25: =SUM(F25:L25) -> 7301086
B26: % of Baseline Revenue Protected | C26: 0 | D26: 0 | E26: 0 | F26: =F25/F12 -> 0.0079668111 | G26: =G25/G12 -> 0.010660572 | H26: =H25/H12 -> 0.010339592 | I26: =I25/I12 -> 0.010034913 | J26: =J25/J12 -> 0.025528056 | K26: =K25/K12 -> 0.033465521 | L26: =L25/L12 -> 0.027688052
B30: Total Capital & Operating Investment
B32: Total CapEx (All Phases) | F32: ='Strategic Revenue Model'!C221 -> 30000 | G32: ='Strategic Revenue Model'!D221 -> 96000 | H32: ='Strategic Revenue Model'!E221 -> 80000 | I32: ='Strategic Revenue Model'!F221 -> 80000 | J32: ='Strategic Revenue Model'!G221 -> 700000 | K32: ='Strategic Revenue Model'!H221 -> 165000 | L32: ='Strategic Revenue Model'!I221 -> 0
B33: Total OpEx (All Phases) | F33: ='Strategic Revenue Model'!C222 -> 21500 | G33: ='Strategic Revenue Model'!D222 -> 29000 | H33: ='Strategic Revenue Model'!E222 -> 26500 | I33: ='Strategic Revenue Model'!F222 -> 25500 | J33: ='Strategic Revenue Model'!G222 -> 113241 | K33: ='Strategic Revenue Model'!H222 -> 185401 | L33: ='Strategic Revenue Model'!I222 -> 183901
B35: Net Revenue After Investment | F35: ='Strategic Revenue Model'!C224 -> 300499.42 | G35: ='Strategic Revenue Model'!D224 -> 367799.18 | H35: ='Strategic Revenue Model'!E224 -> 386299.18 | I35: ='Strategic Revenue Model'!F224 -> 387299.18 | J35: ='Strategic Revenue Model'!G224 -> 478016.48 | K35: ='Strategic Revenue Model'!H224 -> 1739314.8 | L35: ='Strategic Revenue Model'!I224 -> 1905814.8
B36: EBIT Margin on Recovery | F36: ='Strategic Revenue Model'!C225 -> 0.85369294 | G36: ='Strategic Revenue Model'!D225 -> 0.74634698 | H36: ='Strategic Revenue Model'!E225 -> 0.78388763 | I36: ='Strategic Revenue Model'!F225 -> 0.78591685 | J36: ='Strategic Revenue Model'!G225 -> 0.37019455 | K36: ='Strategic Revenue Model'!H225 -> 0.83232122 | L36: ='Strategic Revenue Model'!I225 -> 0.91199712
F38: =SUM(F36:L36)/6 -> 0.88072622
F40: =F32+F33 -> 51500 | G40: =G32+G33 -> 125000 | H40: =H32+H33 -> 106500 | I40: =I32+I33 -> 105500 | J40: =J32+J33 -> 813241 | K40: =K32+K33 -> 350401 | L40: =L32+L33 -> 183901

Sheet Strategic Revenue Model
B2: PHASE 1: THE MAZDA Partnership (Short-Term: 2026-2030+)
B3: RAV4 PRIME PRODUCTION SHIFT TO USA
B4: All figures in JPY Millions unless otherwise noted
B6: Years | C6: 2026 | D6: 2027 | E6: 2028 | F6: 2029 | G6: 2030 | H6: 2035 | I6: 2040
B8: PRODUCTION CAPACITY UTILIZATION
B9: MTM Plant Current Capacity (units) | C9: 300000 | D9: 300000 | E9: 300000 | F9: 300000 | G9: 300000 | H9: 300000 | I9: 300000
B10: - Toyota allocated capacity | C10: 150000 | D10: 150000 | E10: 150000 | F10: 150000 | G10: 150000 | H10: 150000 | I10: 150000
B11: - Mazda unused line capacity (available) | C11: 60000 | D11: 60000 | E11: 60000 | F11: 60000 | G11: 60000 | H11: 60000 | I11: 60000
B12: Additional 3rd shift capacity (units) | D12: 20000 | E12: 20000 | F12: 20000 | G12: 20000 | H12: 20000 | I12: 20000
B13: Total available capacity for RAV4 Prime | C13: =C11+C12 -> 60000 | D13: =D11+D12 -> 80000 | E13: =E11+E12 -> 80000 | F13: =F11+F12 -> 80000 | G13: =G11+G12 -> 80000 | H13: =H11+H12 -> 80000 | I13: =I11+I12 -> 80000
B15: PRODUCTION VOLUME STRATEGY
B16: RAV4 Prime units shifted from Japan | C16: 50000 | D16: 70000 | E16: 70000 | F16: 70000 | G16: 70000 | H16: 70000 | I16: 70000 | J16: Assumption: Production Shifting had no hiccup
B17: - Via Mazda spare capacity lease | C17: 50000 | D17: 50000 | E17: 50000 | F17: 50000 | G17: 50000 | H17: 50000 | I17: 50000
B18: - Via 3rd shift expansion | D18: 20000 | E18: 20000 | F18: 20000 | G18: 20000 | H18: 20000 | I18: 20000
B19: Current Corolla/Corolla Cross (maintain) | C19: 150000 | D19: 150000 | E19: 150000 | F19: 150000 | G19: 150000 | H19: 150000 | I19: 150000
B20: Total MTM production volume | C20: =C16+C19 -> 200000 | D20: =D16+D19 -> 220000 | E20: =E16+E19 -> 220000 | F20: =F16+F19 -> 220000 | G20: =G16+G19 -> 220000 | H20: =H16+H19 -> 220000 | I20: =I16+I19 -> 220000
B22: REVENUE DRIVERS (RAV4 Prime only)
B23: Average Selling Price - RAV4 Prime (USD) | C23: 44815 | D23: 44815 | E23: 44815 | F23: 44815 | G23: 44815 | H23: 44815 | I23: 44815 | J23: Assumption : Selling Price remains stagnant throughout years
B24: USD/JPY Rate | C24: 157.09 | D24: 157.09 | E24: 157.09 | F24: 157.09 | G24: 157.09 | H24: 157.09 | I24: 157.09 | J24: Assumption ; USD/JPY rate remains constant over years
B25: Average Selling Price - RAV4 Prime (¥000,000) | C25: =(C23*C24)/1000000 -> 7.0399884 | D25: =(D23*D24)/1000000 -> 7.0399884 | E25: =(E23*E24)/1000000 -> 7.0399884 | F25: =(F23*F24)/1000000 -> 7.0399884 | G25: =(G23*G24)/1000000 -> 7.0399884 | H25: =(H23*H24)/1000000 -> 7.0399884 | I25: =(I23*I24)/1000000 -> 7.0399884
B26: Annual units produced | C26: 50000 | D26: 70000 | E26: 70000 | F26: 70000 | G26: 70000 | H26: 70000 | I26: 70000 | J26: Assumption: no increase in production
B27: Gross Revenue Generated | C27: =C26*C25 -> 351999.42 | D27: =D26*D25 -> 492799.18 | E27: =E26*E25 -> 492799.18 | F27: =F26*F25 -> 492799.18 | G27: =G26*G25 -> 492799.18 | H27: =H26*H25 -> 492799.18 | I27: =I26*I25 -> 492799.18
B29: 200% Tariff Avoided (alternative scenario) | C29: =C27*2 -> 703998.84 | D29: =D27*2 -> 985598.37 | E29: =E27*2 -> 985598.37 | F29: =F27*2 -> 985598.37 | G29: =G27*2 -> 985598.37 | H29: =H27*2 -> 985598.37 | I29: =I27*2 -> 985598.37 | J29: Assumption: 200% tariff stagnant
B30: Effective Revenue Protected | C30: =C29-C27 -> 351999.42 | D30: =D29-D27 -> 492799.18 | E30: =E29-E27 -> 492799.18 | F30: =F29-F27 -> 492799.18 | G30: =G29-G27 -> 492799.18 | H30: =H29-H27 -> 492799.18 | I30: =I29-I27 -> 492799.18
B32: CAPITAL EXPENDITURE (One-Time)
B33: Mazda capacity lease agreement (2-year) | C33: 5000 | J33: Assumption : Both Parties agreed
B34: Plug-in hybrid battery assembly line | C34: 12000
B35: Additional stamping/welding tooling | C35: 8000
B36: 3rd shift infrastructure setup | D36: 15000
B37: Battery logistics integration (NC plant) | C37: 3000
B38: Training facilities & equipment | C38: 2000 | D38: 1000
B39: Total CapEx | C39: =SUM(C33:C38) -> 30000 | D39: =SUM(D33:D38) -> 16000
B41: OPERATING COSTS (Annual)
B42: Direct Labor
B43: - New hires for RAV4 Prime production | C43: 1000 | D43: 1400 | E43: 1400 | F43: 1400 | G43: 1400 | H43: 1400 | I43: 1400
B44: - Average annual cost per worker (¥M) | C44: 8 | D44: 8 | E44: 8 | F44: 8 | G44: 8 | H44: 8 | I44: 8 | J44: Assumption : Wages are stagnant
B45: - Total labor cost | C45: =C43*C44 -> 8000 | D45: =D43*D44 -> 11200 | E45: =E43*E44 -> 11200 | F45: =F43*F44 -> 11200 | G45: =G43*G44 -> 11200 | H45: =H43*H44 -> 11200 | I45: =I43*I44 -> 11200
B47: Supply Chain & Logistics
B48: - Battery pack shipping (NC to AL) | C48: 2500 | D48: 3500 | E48: 3500 | F48: 3500 | G48: 3500 | H48: 3500 | I48: 3500
B49: - Hybrid powertrain components | C49: 1500 | D49: 2100 | E49: 2100 | F49: 2100 | G49: 2100 | H49: 2100 | I49: 2100
...

Sheet 1. Assumptions
B2: TOYOTA U.S. TARIFF ANALYSIS - MODEL ASSUMPTIONS
B5: Tariff Policy
B6: Tariff Rate | C6: 2 | D6: 200% on automotive equipment
B7: Effective Date | C7: 1-Jan-2026
B8: Policy Duration | C8: 5+ years | D8: Assumed permanent
B10: U.S. Market Data
B11: Total U.S. Market 2024 (units) | C11: 15500000
B12: Toyota U.S. Sales 2024 (units) | C12: 2330000
B13: Toyota Market Share | C13: 0.15
B14: Market Growth Rate (BAU) | C14: 0.02 | D14: Annual baseline growth
B15: Price Elasticity of Demand | C15: -1.5 | D15: % volume change per 1% price increase
B17: Toyota Product Mix - U.S.
B18: % Imported from Japan | C18: 0.3 | D18: Prius, 4Runner, Lexus GX/LX/LS
B19: % Made in USA | C19: 0.7 | D19: Camry, Tacoma, Highlander
B21: Pricing & Costs (JPY '000)
B22: ASP - Imported Vehicle | C22: 3500
B23: ASP - US-Made Vehicle | C23: 3200
B24: Cost - Imported (landed) | C24: 2500
B25: Cost - US-Made | C25: 2400
B26: Dealer Margin | C26: 0.12
B27: Target Operating Margin | C27: 0.095
B29: Strategic Response
B30: CapEx per New Plant (JPY M) | C30: 240000
B31: Time to Build | C31: 3 years
B32: Plant Capacity (units/year) | C32: 250000

Sheet 2. Historical Financials
B2: TOYOTA CONSOLIDATED FINANCIALS (JPY Millions)
B5: Fiscal Year Ending March 31 | C5: FY2021 | D5: FY2022 | E5: FY2023 | F5: FY2024 | G5: FY2025 | H5: LTM Dec-25
B6: Total Revenue | C6: 27214593 | D6: 31379507 | E6: 37154298 | F6: 45095325 | G6: 48036704 | H6: 50450763
B7: Growth % | C7: -0.089 | D7: 0.153 | E7: 0.184 | F7: 0.214 | G7: 0.065 | H7: 0.079
B9: Gross Profit | C9: 4832373 | D9: 5971689 | E9: 6308003 | F9: 9370080 | G9: 9567729 | H9: 8877939
B10: Gross Margin % | C10: 0.178 | D10: 0.19 | E10: 0.17 | F10: 0.208 | G10: 0.199 | H10: 0.176
B12: EBIT | C12: 2197748 | D12: 2995712 | E12: 2720013 | F12: 5354697 | G12: 4785277 | H12: 4302507
B13: EBIT Margin % | C13: 0.081 | D13: 0.095 | E13: 0.073 | F13: 0.119 | G13: 0.1 | H13: 0.085
B15: Net Income | C15: 2245261 | D15: 2850110 | E15: 2451318 | F15: 4944933 | G15: 4765086 | H15: 3695588
B16: Net Margin % | C16: 0.083 | D16: 0.091 | E16: 0.066 | F16: 0.11 | G16: 0.099 | H16: 0.073

Sheet 3. BAU Projection
B2: BUSINESS AS USUAL - NO TARIFF SCENARIO (JPY Millions)
B5: Projection (BAU Scenario) | C5: 2026E | D5: 2027E | E5: 2028E | F5: 2029E | G5: 2030E
B6: Total Revenue | C6: 50198356 | D6: =C6*(1+C7) -> 52457282 | E6: 54135212 | F6: 55759268 | G6: 57432046
B7: Growth % | C7: 0.045 | D7: 0.046 | E7: 0.031 | F7: 0.03 | G7: 0.03
B9: North America Revenue (32%) | C9: 16063474 | D9: 16802394 | E9: 17323268 | F9: 17842966 | G9: 18378255
B10: - US Market (90% of NA) | C10: 14457126 | D10: 15122154 | E10: 15590941 | F10: 16058669 | G10: 16540429
B11: - Imported from Japan (30%) | C11: 4337137.9 | D11: 4536646.3 | E11: 4677282.3 | F11: 4817600.8 | G11: 4962128.8
B12: - Made in USA (70%) | C12: 10119989 | D12: 10585508 | E12: 10913659 | F12: 11241068 | G12: 11578301
B13: Rest of World (68%) | C13: 34134882 | D13: 35705086 | E13: 36811944 | F13: 37916302 | G13: 39053792
B15: EBIT | C15: 4768843.8 | D15: 4988210.6 | E15: 5142845.1 | F15: 5297130.5 | G15: 5456044.4
B16: EBIT Margin % | C16: 0.095 | D16: 0.095 | E16: 0.095 | F16: 0.095 | G16: 0.095
B18: Net Income | C18: 3915471.7 | D18: 4095583.4 | E18: 4222546.5 | F18: 4349222.9 | G18: 4479699.6
B19: Net Margin % | C19: 0.078 | D19: 0.078 | E19: 0.078 | F19: 0.078 | G19: 0.078

Sheet 4. Tariff Impact Detail
B2: TARIFF IMPACT CALCULATION - REPRESENTATIVE VEHICLE (JPY '000)
B5: Cost Component | C5: Import (Pre) | D5: Import (Post) | E5: US-Made | F5: Delta
B6: Manufacturing Cost | C6: 2000 | D6: 2000 | E6: 2000
B7: Logistics | C7: 150 | D7: 150 | E7: 50 | F7: -100
B8: Landed Cost | C8: 2150 | D8: 2150 | E8: 2050 | F8: -100
B10: Import Tariff (200%) | D10: 4300 | F10: -4300
B12: Total Cost Basis | C12: 2150 | D12: 6450 | E12: 2050 | F12: -4400
B14: Selling Price (w/ margins) | C14: 2637 | D14: 7910 | E14: 2514 | F14: -5396
B15: Price Increase | D15: 2
B17: Gross Margin % | C17: 0.185 | D17: 0.185 | E17: 0.185
B19: Volume Impact
B20: Expected Volume Change | C20: 0 | D20: -0.85 | E20: 0.15
B22: Conclusion:
B23: Imported vehicles become UNMARKETABLE
B24: Customers shift to US-made or competitors

Sheet 5. Tariff Impact 5Yr
B2: 5-YEAR TARIFF IMPACT PROJECTION (JPY Millions)
B3: Scenario: Full Tariff Applied, No Strategic Response
B6: Metrics | C6: 2025A | D6: 2026E | E6: 2027E | F6: 2028E | G6: 2029E | H6: 2030E
B7: U.S. SALES VOLUME (Units)
B8: Total Toyota U.S. Sales | C8: 2330000 | D8: 1865000 | E8: 1980000 | F8: 2145000 | G8: 2265000 | H8: 2335000
B9: - Imported from Japan | C9: 699000 | D9: 70000 | E9: 105000 | F9: 140000 | G9: 145000 | H9: 150000
B10: - Made in USA | C10: 1631000 | D10: 1795000 | E10: 1875000 | F10: 2005000 | G10: 2120000 | H10: 2185000
B12: Volume Change vs BAU
B13: Total Volume Change | C13: 0 | D13: -0.2 | E13: -0.15 | F13: -0.08 | G13: -0.03 | H13: 0
B14: Import Volume Change | C14: 0 | D14: -0.9 | E14: -0.85 | F14: -0.8 | G14: -0.79 | H14: -0.79
B15: US-Made Volume Change | C15: 0 | D15: 0.1 | E15: 0.15 | F15: 0.23 | G15: 0.3 | H15: 0.34
B17: U.S. REVENUE (JPY Millions)
B18: Revenue - Imported | C18: 2446500000 | D18: 245000000 | E18: 367500000 | F18: 490000000 | G18: 507500000 | H18: 525000000
B19: Revenue - US-Made | C19: 5219200000 | D19: 5744000000 | E19: 6000000000 | F19: 6416000000 | G19: 6784000000 | H19: 6992000000
B20: Total U.S. Revenue | C20: 7665700000 | D20: 5989000000 | E20: 6367500000 | F20: 6906000000 | G20: 7291500000 | H20: 7517000000
B22: Global Revenue
B23: U.S. as % of Global | C23: 0.32 | D23: 0.3 | E23: 0.31 | F23: 0.315 | G23: 0.32 | H23: 0.32
B24: Total Global Revenue | C24: 48036704 | D24: 48500000 | E24: 50100000 | F24: 51900000 | G24: 53300000 | H24: 54600000
B26: PROFITABILITY IMPACT
B27: Operating Margin - Normal | C27: 0.095 | D27: 0.095 | E27: 0.095 | F27: 0.095 | G27: 0.095 | H27: 0.095
B28: Operating Margin - Actual | C28: 0.095 | D28: 0.052 | E28: 0.068 | F28: 0.081 | G28: 0.089 | H28: 0.093
B29: Margin Compression | C29: 0 | D29: -0.043 | E29: -0.027 | F29: -0.014 | G29: -0.006 | H29: -0.002
B31: EBIT | C31: 4785277 | D31: 2522000 | E31: 3406800 | F31: 4203900 | G31: 4743700 | H31: 5077800
B32: EBIT Loss vs BAU | C32: 0 | D32: -2300000 | E32: -1850000 | F32: -1050000 | G32: -450000 | H32: -150000
B34: Net Income | C34: 4765086 | D34: 1969000 | E34: 2657000 | F34: 3278000 | G34: 3698000 | H34: 3959000
B35: Net Income Loss vs BAU | C35: 0 | D35: -1800000 | E35: -1400000 | F35: -800000 | G35: -350000 | H35: -120000
B37: CUMULATIVE 5-YEAR IMPACT
B38: Total EBIT Lost (2026-2030) | H38: -5800000
B39: Total Net Income Lost | H39: -4470000

Sheet 6. Strategic Scenarios
B2: STRATEGIC RESPONSE SCENARIOS - 5 YEAR NPV COMPARISON
B5: Scenario | C5: Year 1 | D5: Year 2 | E5: Year 3 | F5: Year 4 | G5: Year 5 | H5: 5Yr NPV
B7: A. DO NOTHING (Base Case)
B8: EBIT Impact (JPY M) | C8: -2300000 | D8: -1850000 | E8: -1050000 | F8: -450000 | G8: -150000 | H8: -5800000
B9: CapEx Required | C9: 0 | D9: 0 | E9: 0 | F9: 0 | G9: 0 | H9: 0
B10: Net Cash Impact | C10: -2300000 | D10: -1850000 | E10: -1050000 | F10: -450000 | G10: -150000 | H10: -5800000
B12: B. RELOCATE PRODUCTION
B13: EBIT Impact (reduced) | C13: -2300000 | D13: -1500000 | E13: -500000 | F13: 200000 | G13: 500000 | H13: -3600000
B14: CapEx (2 new plants) | C14: -300000 | D14: -300000 | E14: 0 | F14: 0 | G14: 0 | H14: -600000
B15: Net Cash Impact | C15: -2600000 | D15: -1800000 | E15: -500000 | F15: 200000 | G15: 500000 | H15: -4200000
B16: NPV Advantage vs Base | H16: 1600000
B18: C. MARKET EXIT
B19: EBIT Impact | C19: -2300000 | D19: -1200000 | E19: -700000 | F19: -300000 | G19: -100000 | H19: -4600000
B20: CapEx Required | C20: 0 | D20: 0 | E20: 0 | F20: 0 | G20: 0 | H20: 0
B21: Net Cash Impact | C21: -2300000 | D21: -1200000 | E21: -700000 | F21: -300000 | G21: -100000 | H21: -4600000
B22: NPV Advantage vs Base | H22: 1200000
B24: D. ABSORB TARIFF
B25: EBIT Impact (negative) | C25: -3500000 | D25: -3200000 | E25: -2900000 | F25: -2600000 | G25: -2400000 | H25: -14600000
B26: Net Cash Impact | C26: -3500000 | D26: -3200000 | E26: -2900000 | F26: -2600000 | G26: -2400000 | H26: -14600000
B27: NPV vs Base | H27: -8800000
B30: RECOMMENDED: B. RELOCATE PRODUCTION
